Workbook

Sheet Sheet1
A1: Order_ID | B1: Order_Date | C1: Region | D1: Sales_Rep | E1: Product | F1: Category | G1: Units_Sold | H1: Unit_Price | I1: Sales_Amount | J1: Cost | K1: Profit | L1: Customer_Rating | M1: Bonus | N1: Performance_Score
A2: ORD0001 | B2: 46042 | C2: North | D2: Priya | E2: Laptop | F2: Electronics | G2: 8 | H2: 52884 | I2: 423072 | J2: 275584 | K2: 147488 | L2: 4.5 | M2: 9111 | N2: =ROUND(I2/J2*L2,2) -> 6.91
A3: ORD0002 | B3: 46052 | C3: North | D3: Rahul | E3: Desk | F3: Furniture | G3: 10 | H3: 12681 | I3: 126810 | J3: 70170 | K3: 56640 | L3: 3.8 | M3: 18604 | N3: =ROUND(I3/J3*L3,2) -> 6.87
A4: ORD0003 | B4: 46192 | C4: East | D4: Pooja | E4: Tablet | F4: Electronics | G4: 15 | H4: 20473 | I4: 307095 | J4: 185415 | K4: 121680 | L4: 2.5 | M4: 17194 | N4: =ROUND(I4/J4*L4,2) -> 4.14
A5: ORD0004 | B5: 46088 | C5: West | D5: Rahul | E5: Printer | F5: Electronics | G5: 12 | H5: 10572 | I5: 126864 | J5: 100080 | K5: 26784 | L5: 4.5 | M5: 6846 | N5: =ROUND(I5/J5*L5,2) -> 5.7
A6: ORD0005 | B6: 46114 | C6: West | D6: Rahul | E6: Desk | F6: Furniture | G6: 17 | H6: 9731 | I6: 165427 | J6: 117011 | K6: 48416 | L6: 2.7 | M6: 9424 | N6: =ROUND(I6/J6*L6,2) -> 3.82
A7: ORD0006 | B7: 46121 | C7: East | D7: Priya | E7: Mobile | F7: Electronics | G7: 4 | H7: 25302 | I7: 101208 | J7: 70888 | K7: 30320 | L7: 3 | M7: 13636 | N7: =ROUND(I7/J7*L7,2) -> 4.28
A8: ORD0007 | B8: 46177 | C8: North | D8: Priya | E8: Tablet | F8: Electronics | G8: 2 | H8: 17049 | I8: 34098 | J8: 24600 | K8: 9498 | L8: 3.5 | M8: 14330 | N8: =ROUND(I8/J8*L8,2) -> 4.85
A9: ORD0008 | B9: 46047 | C9: North | D9: Vikas | E9: Desk | F9: Furniture | G9: 9 | H9: 8298 | I9: 74682 | J9: 58707 | K9: 15975 | L9: 4.8 | M9: 6212 | N9: =ROUND(I9/J9*L9,2) -> 6.11
A10: ORD0009 | B10: 46098 | C10: South | D10: Vikas | E10: Laptop | F10: Electronics | G10: 17 | H10: 50547 | I10: 859299 | J10: 610232 | K10: 249067 | L10: 3.9 | M10: 12223 | N10: =ROUND(I10/J10*L10,2) -> 5.49
A11: ORD0010 | B11: 46107 | C11: East | D11: Pooja | E11: Laptop | F11: Electronics | G11: 9 | H11: 50985 | I11: 458865 | J11: 323217 | K11: 135648 | L11: 3.3 | M11: 9515 | N11: =ROUND(I11/J11*L11,2) -> 4.68
A12: ORD0011 | B12: 46117 | C12: West | D12: Neha | E12: Mobile | F12: Electronics | G12: 4 | H12: 23654 | I12: 94616 | J12: 71880 | K12: 22736 | L12: 4.5 | M12: 6245 | N12: =ROUND(I12/J12*L12,2) -> 5.92
A13: ORD0012 | B13: 46120 | C13: North | D13: Karan | E13: Printer | F13: Electronics | G13: 19 | H13: 13121 | I13: 249299 | J13: 166402 | K13: 82897 | L13: 3.3 | M13: 13125 | N13: =ROUND(I13/J13*L13,2) -> 4.94
... A201: ORD0200 | B201: 46061 | C201: South | D201: Priya | E201: Mobile | F201: Electronics | G201: 9 | H201: 27558 | I201: 248022 | J201: 157860 | K201: 90162 | L201: 4.1 | M201: 15241 | N201: =ROUND(I201/J201*L201,2) -> 6.44

Sheet Solutions
A1: Question | B1: Solution (Formula)
A2: Basic Math Functions
A3: Q1. Total Sales Amount | B3: =SUM(Sheet1!I2:I201) -> 42764735
A4: Q2. Total Profit | B4: =SUM(Sheet1!K2:K201) -> 13941975
A5: Q3. Average Sales Amount | B5: =AVERAGE(Sheet1!I2:I201) -> 213823.67
A6: Q4. Average Customer Rating | B6: =AVERAGE(Sheet1!L2:L201) -> 3.7445
A7: Q5. Total Orders (Count) | B7: =COUNTA(Sheet1!A2:A201) -> 200
A8: Maximum & Minimum Functions
A9: Q6. Highest Sales Amount | B9: =MAX(Sheet1!I2:I201) -> 997100
A10: Q7. Lowest Profit | B10: =MIN(Sheet1!K2:K201) -> -13685
A11: Q8. 2nd Highest Sales Amount | B11: =LARGE(Sheet1!I2:I201,2) -> 976240
A12: Q9. 5th Smallest Profit | B12: =SMALL(Sheet1!K2:K201,5) -> -1660
A13: Q10. Count of Available Customer Ratings | B13: =COUNT(Sheet1!L2:L201) -> 200
A14: Rounding Functions
A15: Q11. Round Average Sales Amount to 2 decimals | B15: =ROUND(AVERAGE(Sheet1!I2:I201),2) -> 213823.68
A16: Q12. Round Highest Sales Amount to nearest 1000 | B16: =ROUND(MAX(Sheet1!I2:I201),-3) -> 997000
A17: Q13. Round DOWN Average Customer Rating to 0 decimals | B17: =ROUNDDOWN(AVERAGE(Sheet1!L2:L201),0) -> 3
A18: Q14. Round UP Average Profit to nearest hundred | B18: =ROUNDUP(AVERAGE(Sheet1!K2:K201),-2) -> 69800
A19: Advanced Math Functions
A20: Q15. Absolute Value of Minimum Profit | B20: =ABS(MIN(Sheet1!K2:K201)) -> 13685
A21: Q16. Total Orders Even or Odd | B21: =IF(ISEVEN(COUNTA(Sheet1!A2:A201)),"Even","Odd") -> Even
A22: Q17. Square Root of Highest Sales Amount | B22: =SQRT(MAX(Sheet1!I2:I201)) -> 998.54895
A23: Q18. Cube of Average Units Sold | B23: =POWER(AVERAGE(Sheet1!G2:G201),3) -> 1151.0226
A24: Random Functions
A25: Q19. Random Bonus Amount (₹5,000 - ₹20,000) per Sales Rep | B25: =RANDBETWEEN(5000,20000) -> 9256
A26: Challenge Question - Performance Score
A27: Q20b. Highest Performance Score | B27: =MAX(Sheet1!N2:N201) -> 14.7
A28: Q20c. Average Performance Score | B28: =AVERAGE(Sheet1!N2:N201) -> 5.80295
A29: Q20d. Top 3 Performance Scores - 1st | B29: =LARGE(Sheet1!N2:N201,1) -> 14.7
A30: Q20e. Top 3 Performance Scores - 2nd | B30: =LARGE(Sheet1!N2:N201,2) -> 13.31
A31: Q20f. Top 3 Performance Scores - 3rd | B31: =LARGE(Sheet1!N2:N201,3) -> 12.96
A32: SUMIF & SUMIFS
A33: Q21. Total Sales Amount - North Region | B33: =SUMIF(Sheet1!C2:C201,"North",Sheet1!I2:I201) -> 13294988
A34: Q22. Total Profit - Electronics Category | B34: =SUMIF(Sheet1!F2:F201,"Electronics",Sheet1!K2:K201) -> 12192923
A35: Q23. Total Sales Amount - Laptop Product | B35: =SUMIF(Sheet1!E2:E201,"Laptop",Sheet1!I2:I201) -> 18790571
A36: Q24. Total Sales Amount (Region=North AND Product=Laptop) | B36: =SUMIFS(Sheet1!I2:I201,Sheet1!C2:C201,"North",Sheet1!E2:E201,"Laptop") -> 6115056
A37: Q25. Total Profit (Region=South AND Category=Furniture) | B37: =SUMIFS(Sheet1!K2:K201,Sheet1!C2:C201,"South",Sheet1!F2:F201,"Furniture") -> 528257
A38: COUNTIF & COUNTIFS
A39: Q26. Count Orders - West Region | B39: =COUNTIF(Sheet1!C2:C201,"West") -> 53
A40: Q27. Count Orders where Rating > 4 | B40: =COUNTIF(Sheet1!L2:L201,">4") -> 80
...
