Workbook

Sheet Employee_Master
A1: Emp_ID | B1: Emp_Name | C1: Department | D1: Designation | E1: Manager | F1: Branch | G1: Region | H1: State | I1: City | J1: Gender | K1: DOJ | L1: Experience | M1: Salary | N1: Bonus | O1: Rating | P1: Status | Q1: Shift | R1: Grade | S1: Email | T1: Phone
A2: EMP0001 | B2: Nisha | C2: IT | D2: Associate | E2: Meena | F2: Mumbai | G2: West | H2: Delhi | I2: Lucknow | J2: Female | K2: 43589 | L2: 3 | M2: 79411 | N2: 6640 | O2: 3.1 | P2: Active | Q2: Evening | R2: A | S2: nisha1@company.com | T2: 9832926554
A3: EMP0002 | B3: Ankit | C3: Sales | D3: Manager | E3: Sunil | F3: Pune | G3: East | H3: Telangana | I3: Mumbai | J3: Male | K3: 44081 | L3: 8 | M3: 62983 | N3: 3412 | O3: 4 | P3: Inactive | Q3: General | R3: A | S3: ankit2@company.com | T3: 9889479538
A4: EMP0003 | B4: Neha | C4: IT | D4: Manager | E4: Rajesh | F4: Hyderabad | G4: East | H4: Maharashtra | I4: Pune | J4: Male | K4: 45519 | L4: 1 | M4: 70461 | N4: 10296 | O4: 4.5 | P4: Active | Q4: General | R4: B | S4: neha3@company.com | T4: 9865327585
A5: EMP0004 | B5: Amit | C5: MIS | D5: Executive | E5: Deepak | F5: Mumbai | G5: South | H5: Delhi | I5: Lucknow | J5: Male | K5: 45078 | L5: 5 | M5: 92771 | N5: 4688 | O5: 3.8 | P5: Active | Q5: Morning | R5: B | S5: amit4@company.com | T5: 9821866564
A6: EMP0005 | B6: Neha | C6: MIS | D6: Associate | E6: Rajesh | F6: Mumbai | G6: West | H6: Delhi | I6: Hyderabad | J6: Female | K6: 43980 | L6: 1 | M6: 28926 | N6: 10207 | O6: 3.4 | P6: Active | Q6: Evening | R6: C | S6: neha5@company.com | T6: 9822446249
A7: EMP0006 | B7: Sneha | C7: HR | D7: Senior Analyst | E7: Rajesh | F7: Pune | G7: South | H7: Karnataka | I7: Mumbai | J7: Female | K7: 43954 | L7: 13 | M7: 52955 | N7: 8154 | O7: 3.1 | P7: Active | Q7: Evening | R7: C | S7: sneha6@company.com | T7: 9880322440
A8: EMP0007 | B8: Pooja | C8: Sales | D8: Senior Analyst | E8: Sunil | F8: Pune | G8: West | H8: Maharashtra | I8: Delhi | J8: Female | K8: 45241 | L8: 5 | M8: 76889 | N8: 14375 | O8: 4.2 | P8: Inactive | Q8: Evening | R8: B | S8: pooja7@company.com | T8: 9831613972
A9: EMP0008 | B9: Priya | C9: HR | D9: Executive | E9: Anita | F9: Lucknow | G9: North | H9: Karnataka | I9: Delhi | J9: Male | K9: 43333 | L9: 11 | M9: 33485 | N9: 13539 | O9: 3.6 | P9: Active | Q9: General | R9: A | S9: priya8@company.com | T9: 9834268094
A10: EMP0009 | B10: Amit | C10: Operations | D10: Analyst | E10: Deepak | F10: Hyderabad | G10: North | H10: Maharashtra | I10: Hyderabad | J10: Male | K10: 45333 | L10: 15 | M10: 34120 | N10: 5103 | O10: 4.2 | P10: Active | Q10: Evening | R10: C | S10: amit9@company.com | T10: 9816222856
A11: EMP0010 | B11: Simran | C11: HR | D11: Executive | E11: Anita | F11: Lucknow | G11: East | H11: Karnataka | I11: Delhi | J11: Female | K11: 45267 | L11: 7 | M11: 69962 | N11: 9730 | O11: 3.2 | P11: Inactive | Q11: Evening | R11: B | S11: simran10@company.com | T11: 9883463572
A12: EMP0011 | B12: Sneha | C12: Sales | D12: Manager | E12: Rajesh | F12: Hyderabad | G12: East | H12: Maharashtra | I12: Delhi | J12: Female | K12: 44630 | L12: 14 | M12: 65801 | N12: 11898 | O12: 4.2 | P12: Inactive | Q12: Evening | R12: C | S12: sneha11@company.com | T12: 9821169177
A13: EMP0012 | B13: Neha | C13: Operations | D13: Senior Analyst | E13: Rajesh | F13: Lucknow | G13: South | H13: UP | I13: Bengaluru | J13: Male | K13: 44563 | L13: 6 | M13: 49718 | N13: 3331 | O13: 3.7 | P13: Inactive | Q13: General | R13: B | S13: neha12@company.com | T13: 9881377626
A14: EMP0013 | B14: Nisha | C14: Finance | D14: Associate | E14: Deepak | F14: Delhi | G14: North | H14: Delhi | I14: Delhi | J14: Male | K14: 44349 | L14: 0 | M14: 38331 | N14: 6325 | O14: 4.7 | P14: Active | Q14: General | R14: B | S14: nisha13@company.com | T14: 9849233923
... A251: EMP0250 | B251: Simran | C251: HR | D251: Manager | E251: Meena | F251: Pune | G251: East | H251: Maharashtra | I251: Delhi | J251: Male | K251: 43981 | L251: 11 | M251: 89552 | N251: 13971 | O251: 4.1 | P251: Inactive | Q251: Evening | R251: B | S251: simran250@company.com | T251: 9830675379

Sheet Sales_Data
A1: Customer_ID | B1: Customer_Name | C1: Product_ID | D1: Product_Name | E1: Category | F1: Sales_Rep | G1: Region | H1: Branch | I1: Quantity | J1: Unit_Price | K1: Sales_Amount | L1: Cost | M1: Profit | N1: Discount_% | O1: Payment_Mode | P1: Delivery_Status | Q1: Customer_Rating | R1: Customer_Type
A2: CUST1001 | B2: Arjun | C2: P102 | D2: Mobile | E2: Electronics | F2: Rahul | G2: North | H2: Hyderabad | I2: 9 | J2: 24443 | K2: 219987 | L2: 160128 | M2: 59859 | N2: 11 | O2: UPI | P2: Cancelled | Q2: 4.4 | R2: Corporate
A3: CUST1002 | B3: Sonal | C3: P101 | D3: Laptop | E3: Electronics | F3: Amit | G3: West | H3: Mumbai | I3: 12 | J3: 54471 | K3: 653652 | L3: 505020 | M3: 148632 | N3: 10 | O3: UPI | P3: Cancelled | Q3: 3.4 | R3: Corporate
A4: CUST1003 | B4: Rakesh | C4: P101 | D4: Laptop | E4: Electronics | F4: Pooja | G4: West | H4: Mumbai | I4: 15 | J4: 54348 | K4: 815220 | L4: 638850 | M4: 176370 | N4: 13 | O4: Net Banking | P4: Returned | Q4: 4.6 | R4: Corporate
A5: CUST1004 | B5: Pallavi | C5: P102 | D5: Mobile | E5: Electronics | F5: Pooja | G5: South | H5: Delhi | I5: 8 | J5: 24494 | K5: 195952 | L5: 138696 | M5: 57256 | N5: 4 | O5: UPI | P5: Delivered | Q5: 4.7 | R5: Corporate
A6: CUST1005 | B6: Arjun | C6: P101 | D6: Laptop | E6: Electronics | F6: Karan | G6: East | H6: Delhi | I6: 14 | J6: 56410 | K6: 789740 | L6: 595392 | M6: 194348 | N6: 11 | O6: UPI | P6: Returned | Q6: 4.6 | R6: Corporate
A7: CUST1006 | B7: Arjun | C7: P102 | D7: Mobile | E7: Electronics | F7: Rahul | G7: South | H7: Pune | I7: 13 | J7: 26391 | K7: 343083 | L7: 240097 | M7: 102986 | N7: 4 | O7: Net Banking | P7: Returned | Q7: 4 | R7: Retail
A8: CUST1007 | B8: Rakesh | C8: P103 | D8: Printer | E8: Electronics | F8: Karan | G8: West | H8: Lucknow | I8: 2 | J8: 12279 | K8: 24558 | L8: 18094 | M8: 6464 | N8: 19 | O8: Card | P8: Pending | Q8: 4.8 | R8: Corporate
A9: CUST1008 | B9: Manoj | C9: P102 | D9: Mobile | E9: Electronics | F9: Vikas | G9: West | H9: Lucknow | I9: 6 | J9: 25757 | K9: 154542 | L9: 109446 | M9: 45096 | N9: 10 | O9: UPI | P9: Returned | Q9: 4 | R9: Corporate
A10: CUST1009 | B10: Manoj | C10: P104 | D10: Chair | E10: Furniture | F10: Rahul | G10: South | H10: Pune | I10: 3 | J10: 4502 | K10: 13506 | L10: 9927 | M10: 3579 | N10: 14 | O10: Net Banking | P10: Delivered | Q10: 5 | R10: Corporate
A11: CUST1010 | B11: Mohit | C11: P103 | D11: Printer | E11: Electronics | F11: Vikas | G11: North | H11: Bengaluru | I11: 9 | J11: 13346 | K11: 120114 | L11: 81621 | M11: 38493 | N11: 16 | O11: Cash | P11: Pending | Q11: 3.6 | R11: Retail
A12: CUST1011 | B12: Arjun | C12: P106 | D12: Tablet | E12: Electronics | F12: Amit | G12: West | H12: Lucknow | I12: 4 | J12: 18998 | K12: 75992 | L12: 49920 | M12: 26072 | N12: 18 | O12: UPI | P12: Returned | Q12: 4.3 | R12: Corporate
A13: CUST1012 | B13: Pallavi | C13: P102 | D13: Mobile | E13: Electronics | F13: Priya | G13: East | H13: Delhi | I13: 12 | J13: 24068 | K13: 288816 | L13: 209076 | M13: 79740 | N13: 17 | O13: Net Banking | P13: Cancelled | Q13: 3.6 | R13: Corporate
... A251: CUST1250 | B251: Sonal | C251: P104 | D251: Chair | E251: Furniture | F251: Karan | G251: South | H251: Pune | I251: 7 | J251: 4040 | K251: 28280 | L251: 25172 | M251: 3108 | N251: 12 | O251: Cash | P251: Delivered | Q251: 3 | R251: Retail

Sheet Helper_Data
A1: Monthly Sales Table (Sample data for HLOOKUP practice — Sales_Rep: Rahul)
A3: Month | B3: Jan | C3: Feb | D3: Mar | E3: Apr | F3: May | G3: Jun | H3: Jul | I3: Aug | J3: Sep | K3: Oct | L3: Nov | M3: Dec
A4: Sales | B4: 185000 | C4: 192000 | D4: 204000 | E4: 176000 | F4: 198000 | G4: 221000 | H4: 209000 | I4: 215000 | J4: 198500 | K4: 226000 | L4: 231000 | M4: 248000
A6: Horizontal Product List (Sample data for TRANSPOSE — Q36)
A8: Product_ID | B8: P101 | C8: P102 | D8: P103 | E8: P104 | F8: P105 | G8: P106
A9: Product_Name | B9: Laptop | C9: Mobile | D9: Printer | E9: Chair | F9: Desk | G9: Tablet

Sheet Solutions
A1: Level | B1: Q# | C1: Question | D1: Function Used | E1: Input | F1: Formula (reference) | G1: Result
A2: LEVEL 1 - VLOOKUP (Employee_Master)
B3: Q1 | C3: Find the Employee Name using Employee ID | D3: VLOOKUP | E3: EMP0001 | F3: '=VLOOKUP(E3,Employee_Master!A:T,2,FALSE) | G3: =VLOOKUP(E3,Employee_Master!A:T,2,FALSE()) -> Nisha
B4: Q2 | C4: Find the Department using Employee ID | D4: VLOOKUP | E4: EMP0001 | F4: '=VLOOKUP(E4,Employee_Master!A:T,3,FALSE) | G4: =VLOOKUP(E4,Employee_Master!A:T,3,FALSE()) -> IT
B5: Q3 | C5: Find the Designation using Employee ID | D5: VLOOKUP | E5: EMP0001 | F5: '=VLOOKUP(E5,Employee_Master!A:T,4,FALSE) | G5: =VLOOKUP(E5,Employee_Master!A:T,4,FALSE()) -> Associate
B6: Q4 | C6: Find the Manager using Employee ID | D6: VLOOKUP | E6: EMP0001 | F6: '=VLOOKUP(E6,Employee_Master!A:T,5,FALSE) | G6: =VLOOKUP(E6,Employee_Master!A:T,5,FALSE()) -> Meena
B7: Q5 | C7: Find the Branch using Employee ID | D7: VLOOKUP | E7: EMP0001 | F7: '=VLOOKUP(E7,Employee_Master!A:T,6,FALSE) | G7: =VLOOKUP(E7,Employee_Master!A:T,6,FALSE()) -> Mumbai
B8: Q6 | C8: Find the Region using Employee ID | D8: VLOOKUP | E8: EMP0001 | F8: '=VLOOKUP(E8,Employee_Master!A:T,7,FALSE) | G8: =VLOOKUP(E8,Employee_Master!A:T,7,FALSE()) -> West
B9: Q7 | C9: Find the Salary using Employee ID | D9: VLOOKUP | E9: EMP0001 | F9: '=VLOOKUP(E9,Employee_Master!A:T,13,FALSE) | G9: =VLOOKUP(E9,Employee_Master!A:T,13,FALSE()) -> 79411
B10: Q8 | C10: Find the Bonus using Employee ID | D10: VLOOKUP | E10: EMP0001 | F10: '=VLOOKUP(E10,Employee_Master!A:T,14,FALSE) | G10: =VLOOKUP(E10,Employee_Master!A:T,14,FALSE()) -> 6640
B11: Q9 | C11: Find the Rating using Employee ID | D11: VLOOKUP | E11: EMP0001 | F11: '=VLOOKUP(E11,Employee_Master!A:T,15,FALSE) | G11: =VLOOKUP(E11,Employee_Master!A:T,15,FALSE()) -> 3.1
B12: Q10 | C12: Employee Report: enter Employee ID -> auto-displays full profile below | D12: VLOOKUP | E12: EMP0250 | F12: '=VLOOKUP(E12,Employee_Master!A:T,2,FALSE) | G12: =VLOOKUP(E12,Employee_Master!A:T,2,FALSE()) -> Simran
C13: -> Department | D13: VLOOKUP | F13: '=VLOOKUP(E12,Employee_Master!A:T,3,FALSE) | G13: =VLOOKUP(E12,Employee_Master!A:T,3,FALSE()) -> HR
C14: -> Designation | D14: VLOOKUP | F14: '=VLOOKUP(E12,Employee_Master!A:T,4,FALSE) | G14: =VLOOKUP(E12,Employee_Master!A:T,4,FALSE()) -> Manager
C15: -> Manager | D15: VLOOKUP | F15: '=VLOOKUP(E12,Employee_Master!A:T,5,FALSE) | G15: =VLOOKUP(E12,Employee_Master!A:T,5,FALSE()) -> Meena
C16: -> Branch | D16: VLOOKUP | F16: '=VLOOKUP(E12,Employee_Master!A:T,6,FALSE) | G16: =VLOOKUP(E12,Employee_Master!A:T,6,FALSE()) -> Pune
C17: -> Region | D17: VLOOKUP | F17: '=VLOOKUP(E12,Employee_Master!A:T,7,FALSE) | G17: =VLOOKUP(E12,Employee_Master!A:T,7,FALSE()) -> East
C18: -> Salary | D18: VLOOKUP | F18: '=VLOOKUP(E12,Employee_Master!A:T,13,FALSE) | G18: =VLOOKUP(E12,Employee_Master!A:T,13,FALSE()) -> 89552
C19: -> Bonus | D19: VLOOKUP | F19: '=VLOOKUP(E12,Employee_Master!A:T,14,FALSE) | G19: =VLOOKUP(E12,Employee_Master!A:T,14,FALSE()) -> 13971
C20: -> Rating | D20: VLOOKUP | F20: '=VLOOKUP(E12,Employee_Master!A:T,15,FALSE) | G20: =VLOOKUP(E12,Employee_Master!A:T,15,FALSE()) -> 4.1
C21: -> Status | D21: VLOOKUP | F21: '=VLOOKUP(E12,Employee_Master!A:T,16,FALSE) | G21: =VLOOKUP(E12,Employee_Master!A:T,16,FALSE()) -> Inactive
A22: LEVEL 2 - XLOOKUP (Sales_Data)
B23: Q11 | C23: Find the Customer Name using Customer ID | D23: XLOOKUP | E23: CUST1001 | F23: '=XLOOKUP(E23,Sales_Data!A:A,Sales_Data!B:B) | G23: =INDEX(Sales_Data!B:B,MATCH(E23,Sales_Data!A:A,0)) -> Arjun
B24: Q12 | C24: Find the Product Name using Product ID | D24: XLOOKUP | E24: P102 | F24: '=XLOOKUP(E24,Sales_Data!C:C,Sales_Data!D:D) | G24: =INDEX(Sales_Data!D:D,MATCH(E24,Sales_Data!C:C,0)) -> Mobile
B25: Q13 | C25: Find the Category using Product ID | D25: XLOOKUP | E25: P102 | F25: '=XLOOKUP(E25,Sales_Data!C:C,Sales_Data!E:E) | G25: =INDEX(Sales_Data!E:E,MATCH(E25,Sales_Data!C:C,0)) -> Electronics
B26: Q14 | C26: Find the Sales Amount using Order ID (Customer_ID used as row key - no Order_ID column in dataset) | D26: XLOOKUP | E26: CUST1001 | F26: '=XLOOKUP(E26,Sales_Data!A:A,Sales_Data!K:K) | G26: =INDEX(Sales_Data!K:K,MATCH(E26,Sales_Data!A:A,0)) -> 219987
B27: Q15 | C27: Find the Profit using Order ID (Customer_ID used as row key) | D27: XLOOKUP | E27: CUST1001 | F27: '=XLOOKUP(E27,Sales_Data!A:A,Sales_Data!M:M) | G27: =INDEX(Sales_Data!M:M,MATCH(E27,Sales_Data!A:A,0)) -> 59859
B28: Q16 | C28: Find the Payment Mode using Order ID (Customer_ID used as row key) | D28: XLOOKUP | E28: CUST1001 | F28: '=XLOOKUP(E28,Sales_Data!A:A,Sales_Data!O:O) | G28: =INDEX(Sales_Data!O:O,MATCH(E28,Sales_Data!A:A,0)) -> UPI
B29: Q17 | C29: Find the Delivery Status using Order ID (Customer_ID used as row key) | D29: XLOOKUP | E29: CUST1001 | F29: '=XLOOKUP(E29,Sales_Data!A:A,Sales_Data!P:P) | G29: =INDEX(Sales_Data!P:P,MATCH(E29,Sales_Data!A:A,0)) -> Cancelled
B30: Q18 | C30: Find the Customer Rating using Customer ID | D30: XLOOKUP | E30: CUST1001 | F30: '=XLOOKUP(E30,Sales_Data!A:A,Sales_Data!Q:Q) | G30: =INDEX(Sales_Data!Q:Q,MATCH(E30,Sales_Data!A:A,0)) -> 4.4
B31: Q19 | C31: Return "Order Not Found" if the entered Order ID (Customer_ID) does not exist | D31: XLOOKUP + if_not_found | E31: CUST9999 | F31: '=XLOOKUP(E31,Sales_Data!A:A,Sales_Data!K:K,"Order Not Found") | G31: =IFERROR(INDEX(Sales_Data!K:K,MATCH(E31,Sales_Data!A:A,0)),"Order Not Found") -> Order Not Found
B32: Q20 | C32: Left Lookup: return Product ID using Product Name | D32: XLOOKUP (left lookup) | E32: Mobile | F32: '=XLOOKUP(E32,Sales_Data!D:D,Sales_Data!C:C) | G32: =INDEX(Sales_Data!C:C,MATCH(E32,Sales_Data!D:D,0)) -> P102
A33: LEVEL 3 - INDEX + MATCH (Employee_Master)
B34: Q21 | C34: Find the Salary using Employee ID | D34: INDEX+MATCH | E34: EMP0003 | F34: '=INDEX(Employee_Master!M:M,MATCH(E34,Employee_Master!A:A,0)) | G34: =INDEX(Employee_Master!M:M,MATCH(E34,Employee_Master!A:A,0)) -> 70461
B35: Q22 | C35: Find the Department using Employee ID | D35: INDEX+MATCH | E35: EMP0003 | F35: '=INDEX(Employee_Master!C:C,MATCH(E35,Employee_Master!A:A,0)) | G35: =INDEX(Employee_Master!C:C,MATCH(E35,Employee_Master!A:A,0)) -> IT
B36: Q23 | C36: Find the Manager using Employee ID | D36: INDEX+MATCH | E36: EMP0003 | F36: '=INDEX(Employee_Master!E:E,MATCH(E36,Employee_Master!A:A,0)) | G36: =INDEX(Employee_Master!E:E,MATCH(E36,Employee_Master!A:A,0)) -> Rajesh
B37: Q24 | C37: Find the Branch using Employee ID | D37: INDEX+MATCH | E37: EMP0003 | F37: '=INDEX(Employee_Master!F:F,MATCH(E37,Employee_Master!A:A,0)) | G37: =INDEX(Employee_Master!F:F,MATCH(E37,Employee_Master!A:A,0)) -> Hyderabad
B38: Q25 | C38: Find the Bonus using Employee ID | D38: INDEX+MATCH | E38: EMP0003 | F38: '=INDEX(Employee_Master!N:N,MATCH(E38,Employee_Master!A:A,0)) | G38: =INDEX(Employee_Master!N:N,MATCH(E38,Employee_Master!A:A,0)) -> 10296
B39: Q26 | C39: Find the Rating using Employee ID | D39: INDEX+MATCH | E39: EMP0003 | F39: '=INDEX(Employee_Master!O:O,MATCH(E39,Employee_Master!A:A,0)) | G39: =INDEX(Employee_Master!O:O,MATCH(E39,Employee_Master!A:A,0)) -> 4.5
B40: Q27 | C40: Find the Experience using Employee ID | D40: INDEX+MATCH | E40: EMP0003 | F40: '=INDEX(Employee_Master!L:L,MATCH(E40,Employee_Master!A:A,0)) | G40: =INDEX(Employee_Master!L:L,MATCH(E40,Employee_Master!A:A,0)) -> 1
...
