Workbook

Sheet Employee_Text_Data
A1: Employee_ID | B1: Employee_Name | C1: First_Name | D1: Last_Name | E1: Email | F1: Phone | G1: Address | H1: City | I1: State | J1: Country | K1: Department | L1: Designation | M1: Branch | N1: Customer_Name | O1: Product_Name | P1: Category | Q1: PAN_Number | R1: Aadhaar_Number | S1: Status | T1: Remarks
A2: EMP0001 | B2: Rohit Jain | C2: Rohit | D2: Jain | E2: rohit.jain1@company.com | F2: 9860602579 | G2: House 350, Sector 9, Bengaluru, India | H2: Bengaluru | I2: Karnataka | J2: India | K2: Finance | L2: Manager | M2: South Hub | N2: Pooja Yadav | O2: Tablet | P2: Electronics | Q2: ABCDE2944F | R2: 217590336009 | S2: Active | T2: Active Employee
A3: EMP0002 | B3: Neha Jain | C3: Neha | D3: Jain | E3: neha.jain2@company.com | F3: 9871804690 | G3: House 345, Sector 16, Jaipur | H3: Jaipur | I3: Maharashtra | J3: India | K3: Finance | L3: Analyst | M3: South Hub | N3: Saurabh Patel | O3: Mobile | P3: Electronics | Q3: ABCDE1679F | R3: 949055136975 | S3: Inactive | T3: Active Employee
A4: EMP0003 | B4: Pooja Jain | C4: Pooja | D4: Jain | E4: pooja.jain3@company.com | F4: 9854340096 | G4: House 719, Sector 49, Pune | H4: Pune | I4: Maharashtra | J4: India | K4: Operations | L4: Executive | M4: East Hub | N4: Rahul Sharma | O4: Printer | P4: Electronics | Q4: ABCDE9455F | R4: 665802038075 | S4: Active | T4: Promotion Due
A5: EMP0004 | B5: Ankit Singh | C5: Ankit | D5: Singh | E5: ankit.singh4@company.com | F5: 9860357380 | G5: House 607, Sector 40, Patna | H5: Patna | I5: Maharashtra | J5: India | K5: Operations | L5: Executive | M5: South Hub | N5: Kavita Singh | O5: Mobile | P5: Electronics | Q5: ABCDE4514F | R5: 575234979554 | S5: Inactive | T5: On Leave
A6: EMP0005 | B6: Kavita Yadav | C6: Kavita | D6: Yadav | E6: kavita.yadav5@company.com | F6: 9854893352 | G6: House 861, Sector 22, Bengaluru | H6: Bengaluru | I6: Delhi | J6: India | K6: HR | L6: Manager | M6: West Hub | N6: Riya Sharma | O6: Monitor | P6: Electronics | Q6: ABCDE1991F | R6: 561980723607 | S6: Active | T6: Promotion Due
A7: EMP0006 | B7: Rahul Mishra | C7: Rahul | D7: Mishra | E7: rahul.mishra6@company.com | F7: 9844999584 | G7: House 898, Sector 4, Pune | H7: Pune | I7: Telangana | J7: India | K7: Sales | L7: Associate | M7: South Hub | N7: Nisha Mishra | O7: Keyboard | P7: Accessories | Q7: ABCDE6627F | R7: 933289956861 | S7: Active | T7: On Leave
A8: EMP0007 | B8: Kavita Singh | C8: Kavita | D8: Singh | E8: kavita.singh7@company.com | F8: 9894362766 | G8: House 863, Sector 35, Jaipur | H8: Jaipur | I8: UP | J8: India | K8: HR | L8: Senior Analyst | M8: North Hub | N8: Saurabh Yadav | O8: Desk | P8: Furniture | Q8: ABCDE7533F | R8: 661179323504 | S8: Active | T8: Active Employee
A9: EMP0008 | B9: Ankit Tiwari | C9: Ankit | D9: Tiwari | E9: ankit.tiwari8@company.com | F9: 9841161112 | G9: House 195, Sector 28, Pune | H9: Pune | I9: Rajasthan | J9: India | K9: HR | L9: Analyst | M9: South Hub | N9: Nisha Patel | O9: Keyboard | P9: Accessories | Q9: ABCDE4937F | R9: 016888669352 | S9: Active | T9: Active Employee
A10: EMP0009 | B10: Nisha Kumar | C10: Nisha | D10: Kumar | E10: nisha.kumar9@company.com | F10: 9837237720 | G10: House 253, Sector 10, Bengaluru | H10: Bengaluru | I10: Telangana | J10: India | K10: Sales | L10: Analyst | M10: West Hub | N10: Kavita Jain | O10: Desk | P10: Furniture | Q10: ABCDE8844F | R10: 912935684636 | S10: Active | T10: On Leave
A11: EMP0010 | B11: Pooja Jain | C11: Pooja | D11: Jain | E11: pooja.jain10@company.com | F11: 9845800734 | G11: House 969, Sector 22, Patna | H11: Patna | I11: Delhi | J11: India | K11: MIS | L11: Analyst | M11: West Hub | N11: Ankit Yadav | O11: Laptop | P11: Electronics | Q11: ABCDE5353F | R11: 175539089868 | S11: Inactive | T11: Transferred
A12: EMP0011 | B12: Kavita Verma | C12: Kavita | D12: Verma | E12: kavita.verma11@company.com | F12: 9856728305 | G12: House 354, Sector 44, Lucknow | H12: Lucknow | I12: Delhi | J12: India | K12: MIS | L12: Analyst | M12: North Hub | N12: Priya Yadav | O12: Mobile | P12: Electronics | Q12: ABCDE7522F | R12: 294395270132 | S12: Active | T12: Promotion Due
... A251: EMP0250 | B251: Riya Tiwari | C251: Riya | D251: Tiwari | E251: riya.tiwari250@company.com | F251: 9841503472 | G251: House 107, Sector 36, Jaipur | H251: Jaipur | I251: Maharashtra | J251: India | K251: IT | L251: Senior Analyst | M251: North Hub | N251: Sneha Sharma | O251: Tablet | P251: Electronics | Q251: ABCDE5204F | R251: 227414218694 | S251: Inactive | T251: New Joiner

Sheet Solutions
A1: Part | B1: Q# | C1: Question | D1: Function Used | E1: Input (Employee ID) | F1: Formula | G1: Result
A2: PART 1 - LEFT, RIGHT, MID, LEN
B3: Q1 | C3: Extract the first 3 characters from Employee ID | D3: LEFT | E3: EMP0001 | F3: '=LEFT(E3,3) | G3: =LEFT(E3,3) -> EMP
B4: Q2 | C4: Extract the last 4 digits from Employee ID | D4: RIGHT | E4: EMP0001 | F4: '=RIGHT(E4,4) | G4: =RIGHT(E4,4) -> 0001
B5: Q3 | C5: Extract the first 5 characters from Phone Number | D5: LEFT | E5: EMP0001 | F5: '=LEFT(INDEX(Employee_Text_Data!F:F,MATCH(E5,Employee_Text_Data!A:A,0)),5) | G5: =LEFT(INDEX(Employee_Text_Data!F:F,MATCH(E5,Employee_Text_Data!A:A,0)),5) -> 98606
B6: Q4 | C6: Extract the last 4 digits of Phone Number | D6: RIGHT | E6: EMP0001 | F6: '=RIGHT(INDEX(Employee_Text_Data!F:F,MATCH(E6,Employee_Text_Data!A:A,0)),4) | G6: =RIGHT(INDEX(Employee_Text_Data!F:F,MATCH(E6,Employee_Text_Data!A:A,0)),4) -> 2579
B7: Q5 | C7: Extract the first 6 characters of PAN Number | D7: LEFT | E7: EMP0001 | F7: '=LEFT(INDEX(Employee_Text_Data!Q:Q,MATCH(E7,Employee_Text_Data!A:A,0)),6) | G7: =LEFT(INDEX(Employee_Text_Data!Q:Q,MATCH(E7,Employee_Text_Data!A:A,0)),6) -> ABCDE2
B8: Q6 | C8: Extract the last 4 digits of Aadhaar Number | D8: RIGHT | E8: EMP0001 | F8: '=RIGHT(INDEX(Employee_Text_Data!R:R,MATCH(E8,Employee_Text_Data!A:A,0)),4) | G8: =RIGHT(INDEX(Employee_Text_Data!R:R,MATCH(E8,Employee_Text_Data!A:A,0)),4) -> 6009
B9: Q7 | C9: Extract the first word from Employee Name | D9: LEFT+FIND | E9: EMP0001 | F9: '=LEFT(INDEX(Employee_Text_Data!B:B,MATCH(E9,Employee_Text_Data!A:A,0)),FIND(" ",INDEX(Employee_Text_Data!B:B,MATCH(E9,Employee_Text_Data!A:A,0)))-1) | G9: =LEFT(INDEX(Employee_Text_Data!B:B,MATCH(E9,Employee_Text_Data!A:A,0)),FIND(" ",INDEX(Employee_Text_Data!B:B,MATCH(E9,Employee_Text_Data!A:A,0)))-1) -> Rohit
B10: Q8 | C10: Extract the last name from Employee Name using MID | D10: MID+FIND | E10: EMP0001 | F10: '=MID(INDEX(Employee_Text_Data!B:B,MATCH(E10,Employee_Text_Data!A:A,0)),FIND(" ",INDEX(Employee_Text_Data!B:B,MATCH(E10,Employee_Text_Data!A:A,0)))+1,LEN(INDEX(Employee_Text_Data!B:B,MATCH(E10,Employee_Text_Data!A:A,0)))) | G10: =MID(INDEX(Employee_Text_Data!B:B,MATCH(E10,Employee_Text_Data!A:A,0)),FIND(" ",INDEX(Employee_Text_Data!B:B,MATCH(E10,Employee_Text_Data!A:A,0)))+1,LEN(INDEX(Employee_Text_Data!B:B,MATCH(E10,Employee_Text_Data!A:A,0)))) -> Jain
B11: Q9 | C11: Find the total length of Employee Name | D11: LEN | E11: EMP0001 | F11: '=LEN(INDEX(Employee_Text_Data!B:B,MATCH(E11,Employee_Text_Data!A:A,0))) | G11: =LEN(INDEX(Employee_Text_Data!B:B,MATCH(E11,Employee_Text_Data!A:A,0))) -> 10
B12: Q10 | C12: Find the total number of characters in Email Address | D12: LEN | E12: EMP0001 | F12: '=LEN(INDEX(Employee_Text_Data!E:E,MATCH(E12,Employee_Text_Data!A:A,0))) | G12: =LEN(INDEX(Employee_Text_Data!E:E,MATCH(E12,Employee_Text_Data!A:A,0))) -> 23
A13: PART 2 - TRIM & CLEAN
B14: Q11 | C14: Remove extra spaces from Remarks | D14: TRIM | E14: EMP0001 | F14: '=TRIM(INDEX(Employee_Text_Data!T:T,MATCH(E14,Employee_Text_Data!A:A,0))) | G14: =TRIM(INDEX(Employee_Text_Data!T:T,MATCH(E14,Employee_Text_Data!A:A,0))) -> Active Employee
B15: Q12 | C15: Remove extra spaces from Employee Name | D15: TRIM | E15: EMP0001 | F15: '=TRIM(INDEX(Employee_Text_Data!B:B,MATCH(E15,Employee_Text_Data!A:A,0))) | G15: =TRIM(INDEX(Employee_Text_Data!B:B,MATCH(E15,Employee_Text_Data!A:A,0))) -> Rohit Jain
B16: Q13 | C16: Clean hidden characters from Address | D16: CLEAN | E16: EMP0001 | F16: '=CLEAN(INDEX(Employee_Text_Data!G:G,MATCH(E16,Employee_Text_Data!A:A,0))) | G16: =CLEAN(INDEX(Employee_Text_Data!G:G,MATCH(E16,Employee_Text_Data!A:A,0))) -> House 350, Sector 9, Bengaluru, India
B17: Q14 | C17: Clean hidden characters from Remarks | D17: CLEAN | E17: EMP0001 | F17: '=CLEAN(INDEX(Employee_Text_Data!T:T,MATCH(E17,Employee_Text_Data!A:A,0))) | G17: =CLEAN(INDEX(Employee_Text_Data!T:T,MATCH(E17,Employee_Text_Data!A:A,0))) -> Active Employee
B18: Q15 | C18: Apply TRIM and CLEAN together on Remarks | D18: TRIM+CLEAN | E18: EMP0001 | F18: '=TRIM(CLEAN(INDEX(Employee_Text_Data!T:T,MATCH(E18,Employee_Text_Data!A:A,0)))) | G18: =TRIM(CLEAN(INDEX(Employee_Text_Data!T:T,MATCH(E18,Employee_Text_Data!A:A,0)))) -> Active Employee
B19: Q16 | C19: Find the length of Employee Name before TRIM | D19: LEN | E19: EMP0001 | F19: '=LEN(INDEX(Employee_Text_Data!B:B,MATCH(E19,Employee_Text_Data!A:A,0))) | G19: =LEN(INDEX(Employee_Text_Data!B:B,MATCH(E19,Employee_Text_Data!A:A,0))) -> 10
B20: Q17 | C20: Find the length of Employee Name after TRIM | D20: LEN+TRIM | E20: EMP0001 | F20: '=LEN(TRIM(INDEX(Employee_Text_Data!B:B,MATCH(E20,Employee_Text_Data!A:A,0)))) | G20: =LEN(TRIM(INDEX(Employee_Text_Data!B:B,MATCH(E20,Employee_Text_Data!A:A,0)))) -> 10
B21: Q18 | C21: Compare both lengths to identify extra spaces (using Remarks, which has real extra spaces) | D21: LEN comparison | E21: EMP0001 | F21: '=LEN(INDEX(Employee_Text_Data!T:T,MATCH(E21,Employee_Text_Data!A:A,0)))-LEN(TRIM(INDEX(Employee_Text_Data!T:T,MATCH(E21,Employee_Text_Data!A:A,0)))) | G21: =LEN(INDEX(Employee_Text_Data!T:T,MATCH(E21,Employee_Text_Data!A:A,0)))-LEN(TRIM(INDEX(Employee_Text_Data!T:T,MATCH(E21,Employee_Text_Data!A:A,0)))) -> 2
A22: PART 3 - CONCAT, CONCATENATE & TEXTJOIN
B23: Q19 | C23: Join First Name and Last Name | D23: CONCATENATE | E23: EMP0001 | F23: '=CONCATENATE(INDEX(Employee_Text_Data!C:C,MATCH(E23,Employee_Text_Data!A:A,0))," ",INDEX(Employee_Text_Data!D:D,MATCH(E23,Employee_Text_Data!A:A,0))) | G23: =CONCATENATE(INDEX(Employee_Text_Data!C:C,MATCH(E23,Employee_Text_Data!A:A,0))," ",INDEX(Employee_Text_Data!D:D,MATCH(E23,Employee_Text_Data!A:A,0))) -> Rohit Jain
B24: Q20 | C24: Create Full Address using Address, City, State and Country | D24: CONCAT | E24: EMP0001 | F24: '=CONCAT(INDEX(Employee_Text_Data!G:G,MATCH(E24,Employee_Text_Data!A:A,0)),", ",INDEX(Employee_Text_Data!H:H,MATCH(E24,Employee_Text_Data!A:A,0)),", ",INDEX(Employee_Text_Data!I:I,MATCH(E24,Employee_Text_Data!A:A,0)),", ",INDEX(Employee_Text_Data!J:J,MATCH(E24,Employee_Text_Data!A:A,0))) | G24: =INDEX(Employee_Text_Data!G:G,MATCH(E24,Employee_Text_Data!A:A,0))&", "&INDEX(Employee_Text_Data!H:H,MATCH(E24,Employee_Text_Data!A:A,0))&", "&INDEX(Employee_Text_Data!I:I,MATCH(E24,Employee_Text_Data!A:A,0))&", "&INDEX(Employee_Text_Data!J:J,MATCH(E24,Employee_Text_Data!A:A,0)) -> House 350, Sector 9, Bengaluru, India, Bengaluru, Karnataka, India
B25: Q21 | C25: Employee Details, e.g. "EMP0001 - Rahul Sharma" | D25: CONCATENATE | E25: EMP0001 | F25: '=CONCATENATE(E25," - ",INDEX(Employee_Text_Data!B:B,MATCH(E25,Employee_Text_Data!A:A,0))) | G25: =CONCATENATE(E25," - ",INDEX(Employee_Text_Data!B:B,MATCH(E25,Employee_Text_Data!A:A,0))) -> EMP0001 - Rohit Jain
B26: Q22 | C26: Join Employee Name and Department | D26: TEXTJOIN | E26: EMP0001 | F26: '=TEXTJOIN(" - ",TRUE,INDEX(Employee_Text_Data!B:B,MATCH(E26,Employee_Text_Data!A:A,0)),INDEX(Employee_Text_Data!K:K,MATCH(E26,Employee_Text_Data!A:A,0))) | G26: =INDEX(Employee_Text_Data!B:B,MATCH(E26,Employee_Text_Data!A:A,0))&" - "&INDEX(Employee_Text_Data!K:K,MATCH(E26,Employee_Text_Data!A:A,0)) -> Rohit Jain - Finance
B27: Q23 | C27: Join Employee Name, Designation and Branch using TEXTJOIN | D27: TEXTJOIN | E27: EMP0001 | F27: '=TEXTJOIN(" | ",TRUE,INDEX(Employee_Text_Data!B:B,MATCH(E27,Employee_Text_Data!A:A,0)),INDEX(Employee_Text_Data!L:L,MATCH(E27,Employee_Text_Data!A:A,0)),INDEX(Employee_Text_Data!M:M,MATCH(E27,Employee_Text_Data!A:A,0))) | G27: =INDEX(Employee_Text_Data!B:B,MATCH(E27,Employee_Text_Data!A:A,0))&" | "&INDEX(Employee_Text_Data!L:L,MATCH(E27,Employee_Text_Data!A:A,0))&" | "&INDEX(Employee_Text_Data!M:M,MATCH(E27,Employee_Text_Data!A:A,0)) -> Rohit Jain | Manager | South Hub
B28: Q24 | C28: Create Email Signature, e.g. "Rahul Sharma | IT | North Hub" | D28: TEXTJOIN | E28: EMP0001 | F28: '=TEXTJOIN(" | ",TRUE,INDEX(Employee_Text_Data!B:B,MATCH(E28,Employee_Text_Data!A:A,0)),INDEX(Employee_Text_Data!K:K,MATCH(E28,Employee_Text_Data!A:A,0)),INDEX(Employee_Text_Data!M:M,MATCH(E28,Employee_Text_Data!A:A,0))) | G28: =INDEX(Employee_Text_Data!B:B,MATCH(E28,Employee_Text_Data!A:A,0))&" | "&INDEX(Employee_Text_Data!K:K,MATCH(E28,Employee_Text_Data!A:A,0))&" | "&INDEX(Employee_Text_Data!M:M,MATCH(E28,Employee_Text_Data!A:A,0)) -> Rohit Jain | Finance | South Hub
B29: Q25 | C29: Create Product Description, e.g. "Laptop - Electronics" | D29: TEXTJOIN | E29: EMP0001 | F29: '=TEXTJOIN(" - ",TRUE,INDEX(Employee_Text_Data!O:O,MATCH(E29,Employee_Text_Data!A:A,0)),INDEX(Employee_Text_Data!P:P,MATCH(E29,Employee_Text_Data!A:A,0))) | G29: =INDEX(Employee_Text_Data!O:O,MATCH(E29,Employee_Text_Data!A:A,0))&" - "&INDEX(Employee_Text_Data!P:P,MATCH(E29,Employee_Text_Data!A:A,0)) -> Tablet - Electronics
B30: Q26 | C30: Create Complete Employee Profile in one cell | D30: TEXTJOIN | E30: EMP0001 | F30: '=TEXTJOIN(" | ",TRUE,E30,INDEX(Employee_Text_Data!B:B,MATCH(E30,Employee_Text_Data!A:A,0)),INDEX(Employee_Text_Data!K:K,MATCH(E30,Employee_Text_Data!A:A,0)),INDEX(Employee_Text_Data!L:L,MATCH(E30,Employee_Text_Data!A:A,0)),INDEX(Employee_Text_Data!M:M,MATCH(E30,Employee_Text_Data!A:A,0)),INDEX(Employee_Text_Data!S:S,MATCH(E30,Employee_Text_Data!A:A,0))) | G30: =E30&" | "&INDEX(Employee_Text_Data!B:B,MATCH(E30,Employee_Text_Data!A:A,0))&" | "&INDEX(Employee_Text_Data!K:K,MATCH(E30,Employee_Text_Data!A:A,0))&" | "&INDEX(Employee_Text_Data!L:L,MATCH(E30,Employee_Text_Data!A:A,0))&" | "&INDEX(Employee_Text_Data!M:M,MATCH(E30,Employee_Text_Data!A:A,0))&" | "&INDEX(Employee_Text_Data!S:S,MATCH(E30,Employee_Text_Data!A:A,0)) -> EMP0001 | Rohit Jain | Finance | Manager | South Hub | Active
A31: PART 4 - FIND & SEARCH
B32: Q27 | C32: Find the position of @ in Email | D32: FIND | E32: EMP0001 | F32: '=FIND("@",INDEX(Employee_Text_Data!E:E,MATCH(E32,Employee_Text_Data!A:A,0))) | G32: =FIND("@",INDEX(Employee_Text_Data!E:E,MATCH(E32,Employee_Text_Data!A:A,0))) -> 12
B33: Q28 | C33: Find the position of "." in Email | D33: FIND | E33: EMP0001 | F33: '=FIND(".",INDEX(Employee_Text_Data!E:E,MATCH(E33,Employee_Text_Data!A:A,0))) | G33: =FIND(".",INDEX(Employee_Text_Data!E:E,MATCH(E33,Employee_Text_Data!A:A,0))) -> 6
B34: Q29 | C34: Find the position of the word "Hub" in Branch | D34: FIND | E34: EMP0001 | F34: '=FIND("Hub",INDEX(Employee_Text_Data!M:M,MATCH(E34,Employee_Text_Data!A:A,0))) | G34: =FIND("Hub",INDEX(Employee_Text_Data!M:M,MATCH(E34,Employee_Text_Data!A:A,0))) -> 7
B35: Q30 | C35: Search the word "Sales" in Department | D35: SEARCH | E35: EMP0021 | F35: '=IFERROR(SEARCH("Sales",INDEX(Employee_Text_Data!K:K,MATCH(E35,Employee_Text_Data!A:A,0))),"Not Found") | G35: =IFERROR(SEARCH("Sales",INDEX(Employee_Text_Data!K:K,MATCH(E35,Employee_Text_Data!A:A,0))),"Not Found") -> 1
B36: Q31 | C36: Check whether Address contains "Sector" | D36: SEARCH+ISNUMBER | E36: EMP0001 | F36: '=IF(ISNUMBER(SEARCH("Sector",INDEX(Employee_Text_Data!G:G,MATCH(E36,Employee_Text_Data!A:A,0)))),"Yes","No") | G36: =IF(ISNUMBER(SEARCH("Sector",INDEX(Employee_Text_Data!G:G,MATCH(E36,Employee_Text_Data!A:A,0)))),"Yes","No") -> Yes
B37: Q32 | C37: Find the position of the first space in Employee Name | D37: FIND | E37: EMP0001 | F37: '=FIND(" ",INDEX(Employee_Text_Data!B:B,MATCH(E37,Employee_Text_Data!A:A,0))) | G37: =FIND(" ",INDEX(Employee_Text_Data!B:B,MATCH(E37,Employee_Text_Data!A:A,0))) -> 6
B38: Q33 | C38: Find the position of India in Address (if present) | D38: SEARCH+IFERROR | E38: EMP0001 | F38: '=IFERROR(SEARCH("India",INDEX(Employee_Text_Data!G:G,MATCH(E38,Employee_Text_Data!A:A,0))),"Not Found") | G38: =IFERROR(SEARCH("India",INDEX(Employee_Text_Data!G:G,MATCH(E38,Employee_Text_Data!A:A,0))),"Not Found") -> 33
B39: Q34 | C39: Compare FIND and SEARCH using mixed-case text (FIND is case-sensitive, SEARCH is not) | D39: FIND vs SEARCH | E39: EMP0001 | F39: '=IFERROR(FIND("JAIN",INDEX(Employee_Text_Data!B:B,MATCH(E39,Employee_Text_Data!A:A,0))),"FIND: not found (case-sensitive)")&" | SEARCH: "&SEARCH("JAIN",INDEX(Employee_Text_Data!B:B,MATCH(E39,Employee_Text_Data!A:A,0))) | G39: =IFERROR(FIND("JAIN",INDEX(Employee_Text_Data!B:B,MATCH(E39,Employee_Text_Data!A:A,0))),"FIND: not found (case-sensitive)")&" | SEARCH: "&SEARCH("JAIN",INDEX(Employee_Text_Data!B:B,MATCH(E39,Employee_Text_Data!A:A,0))) -> FIND: not found (case-sensitive) | SEARCH: 7
A40: PART 5 - SUBSTITUTE & REPLACE
...
